<?xml version="1.0"?>
<robot xmlns:xacro="http://www.ros.org/wiki/xacro">


    <xacro:include filename="materials.xacro"/>
    <xacro:include filename="inertial_macros.xacro"/>

    <link name="base_link">
        <origin xyz="0 0 0.01"/>
    </link>

    <joint name="chassis_joint" type="fixed">
        <parent link="base_link"/>
        <child link="chassis"/>
        <origin xyz="0 0 0.0023" rpy="0 0 ${pi}"/>
    </joint> 


    <link name="chassis">
        <visual>
            <origin xyz="0 0 0"/>
            <geometry>
                <mesh filename="package://pg1_project/description/meshes/BODY.stl" scale="0.001 0.001 0.001"/>
            </geometry>
            <material name="red"/>
        </visual>
        <collision>
            <origin xyz="-0.13 0 0.1"/>
            <geometry>
                <box size="0.4 0.5 0.3"/>
            </geometry>
        </collision>
        <xacro:inertial_box mass="4" x="0.4" y="0.3" z="0.2">
            <origin xyz="0.15 0 0.075" rpy="0 0 0"/>
        </xacro:inertial_box>
    </link>




    <joint name="left_wheel_joint" type="continuous">
        <parent link="base_link"/>
        <child link="left_wheel"/>
        <origin xyz="0 0.2 0" rpy="-${pi/2} 0 0"/>
        <axis xyz="0 0 1"/>
    </joint> 

    <link name="left_wheel">
        <visual>
            <geometry>
                <mesh filename="package://pg1_project/description/meshes/WHEEL.stl" scale="0.001 0.001 0.001"/>
            </geometry>
            <material name="gray"/>
        </visual>
        <collision>
            <geometry>
                <mesh filename="package://pg1_project/description/meshes/WHEEL.stl" scale="0.001 0.001 0.001"/>
            </geometry>
        </collision>
        <xacro:inertial_cylinder mass="3" radius="0.16" length="0.04">
            <origin xyz="0 0 0" rpy="0 0 0"/>
        </xacro:inertial_cylinder>
    </link>




    <joint name="right_wheel_joint" type="continuous">
        <parent link="base_link"/>
        <child link="right_wheel"/>
        <origin xyz="0 -0.2 0" rpy="${pi/2} 0 0"/>
        <axis xyz="0 0 -1"/>
    </joint> 

    <link name="right_wheel">
        <visual>
            <geometry>
                <mesh filename="package://pg1_project/description/meshes/WHEEL.stl" scale="0.001 0.001 0.001"/>
            </geometry>
            <material name="gray"/>
        </visual>
        <collision>
            <geometry>
                <mesh filename="package://pg1_project/description/meshes/WHEEL.stl" scale="0.001 0.001 0.001"/>
            </geometry>
        </collision>
        <xacro:inertial_cylinder mass="3" radius="0.16" length="0.04">
            <origin xyz="0 0 0" rpy="0 0 0"/>
        </xacro:inertial_cylinder>
    </link>



    <joint name="caster_wheel_joint" type="fixed">
        <parent link="base_link"/>
        <child link="caster_wheel"/>
        <origin xyz="0.31 0 -0.04" />
    </joint> 

    <link name="caster_wheel">
        <visual>
            <geometry>
                <cylinder radius="0.02" length="0.07"/>
            </geometry>
            <material name="gray"/>
        </visual>
        <collision>
            <geometry>
                <cylinder radius="0.04" length="0.05"/>
            </geometry>
        </collision>
        <xacro:inertial_sphere mass="0.1" radius="0.05">
            <origin xyz="0 0 0" rpy="0 0 0"/>
        </xacro:inertial_sphere>
    </link>


</robot>